#include <iostream>
#include <stdexcept>

int main() {
    try {
        throw std::runtime_error("Standard exception");
    } catch (const std::runtime_error& e) {
        std::cout << "Caught a runtime_error: " << e.what() << std::endl;
    }
    return 0;
}
